Workbook

Sheet Dashboard
A1: GROUP 8 | IFRS FINANCIAL ACCOUNTING ENGINE | FY 2024
A4: Live Dashboard ● IAS 1 ● IAS 2 ● IAS 7 ● IAS 16 ● IAS 36 ● IAS 38 ● IFRS 16 ● All values auto-update from Journal
A5: =IF(ABS(SOFP!C26-(SOFP!C33+SOFP!C48))<1,"✔ ACCOUNTING EQUATION BALANCED | Assets = Equity + Liabilities","✘ EQUATION ERROR — Check Journal Entries")
A6: KEY PERFORMANCE INDICATORS
A7: 💵 Cash Balance | C7: 📈 Net Revenue | E7: 💰 Net Profit | G7: 🏦 Total Assets | I7: 📊 Total Equity | K7: ⚖️ Current Ratio | M7: 📉 Debt-to-Assets
A8: =General_Ledger!F3 | C8: =SOFP!C26 | E8: =Profit_Loss!C35 | G8: =SOFP!C26 | I8: =SOFP!C33 | K8: =IFERROR(SOFP!C24/SOFP!C46,0) | M8: =IFERROR((SOFP!C39+SOFP!C46)/SOFP!C26,0)
A9: PKR | C9: PKR | E9: PKR | G9: PKR | I9: PKR | K9: x | M9: %
A11: FINANCIAL STATEMENTS SUMMARY
A12: PROFIT & LOSS | H12: FINANCIAL POSITION
A13: Gross Revenue | E13: =Profit_Loss!C5+Profit_Loss!C6 | H13: Total Non-Current Assets | K13: =SOFP!C17
A14: Net Revenue | E14: =Profit_Loss!C7 | H14: Total Current Assets | K14: =SOFP!C24
A15: Total COGS | E15: =Profit_Loss!C11 | H15: TOTAL ASSETS | K15: =SOFP!C26
A16: Gross Profit | E16: =Profit_Loss!C12 | H16: Total Equity | K16: =SOFP!C33
A17: Total Opex | E17: =Profit_Loss!C26 | H17: Non-Current Liabilities | K17: =SOFP!C39
A18: EBIT | E18: =Profit_Loss!C28 | H18: Current Liabilities | K18: =SOFP!C46
A19: Net Profit | E19: =Profit_Loss!C35 | H19: TOTAL LIABILITIES | K19: =SOFP!C48
A20: Total Comprehensive Inc | E20: =Profit_Loss!C39 | H20: Cash Balance | K20: =General_Ledger!F3
A23: NAVIGATION — Click a sheet tab below | All 15 sheets auto-linked via Journal → GL → All Statements
A24: 📋 Journal | B24: 📒 Ledger | C24: ⚖️ Trial Bal | D24: 📦 Inventory | E24: 🏗️ PPE | F24: 📑 Lease | G24: 🏛️ Equity | H24: 💰 P&L | I24: 🏦 SOFP | J24: 💸 Cash Flow | K24: 📝 Notes | L24: 🤖 AI Log | M24: 🔧 Variables | N24: 📥 Input Form

Sheet Variable_Matrix
A1: GROUP 8 — VARIABLE MATRIX
A2: Variable | B2: Symbol | C2: Value (PKR) | D2: Notes
A3: Shares Issued | B3: SHARES | C3: 550000 | D3: Number of ordinary shares issued
A4: Share Price (PKR) | B4: SHARE_PRICE | C4: 28 | D4: PKR per share at issuance
A5: Par Value per Share | B5: PAR_VALUE | C5: 10 | D5: Nominal/par value per share
A6: PPE — Machinery Cost | B6: PPE_COST | C6: 20000000 | D6: IAS 16 Cost Model
A7: Markup % | B7: MARKUP | C7: 0.55 | D7: 55% markup on cost
A8: Annual Lease Payment | B8: LEASE_PMT | C8: 450000 | D8: IFRS 16 annual cash payment
A9: Discount Rate | B9: DISC_RATE | C9: 0.13 | D9: 13% incremental borrowing rate
A10: Lease Term (yrs) | B10: LEASE_TERM | C10: 5 | D10: 5-year lease
A11: Research Expense | B11: RESEARCH | C11: 75000 | D11: IAS 38 — expensed immediately
A12: Development Cost | B12: DEV_COST | C12: 220000 | D12: IAS 38 — capitalised
A13: Recoverable Amount | B13: RECOV_AMT | C13: 18000000 | D13: IAS 36 — higher of FVLCD & VIU
A14: Useful Life — Machinery | B14: USEFUL_LIFE | C14: 60 | D14: Years — straight-line
... A16: Revaluation Gain | B16: REVAL_GAIN | C16: 1000000 | D16: OCI — revaluation surplus on land
A17: Lease PV | B17: LEASE_PV | C17: =PV(C9,C10,-C8) | D17: =PV(13%,5,-450000) — IFRS 16 initial

Sheet Journal
A1: GENERAL JOURNAL — Group 8 | All 35 IFRS Transactions (Expanded Debit/Credit)
A2: Date | B2: Txn ID | C2: Description | D2: Account | E2: Dr/Cr | F2: Amount (PKR) | G2: IFRS Ref | H2: Category | I2: D/C Flag
A3: 2024-01-01 | B3: T01 | C3: Share Issuance — 550k shares @ PKR 28 | D3: Cash | E3: Dr | F3: =Variable_Matrix!C3*Variable_Matrix!C4 | G3: IAS 1 | H3: Equity | I3: 1
A4: 2024-01-01 | B4: T01 | C4: Share Issuance — Share Capital (par 10) | D4: Share Capital | E4: Cr | F4: =Variable_Matrix!C3*Variable_Matrix!C5 | G4: IAS 1 | H4: Equity | I4: -1
A5: 2024-01-01 | B5: T01 | C5: Share Issuance — Share Premium | D5: Share Premium | E5: Cr | F5: =Variable_Matrix!C3*(Variable_Matrix!C4-Variable_Matrix!C5) | G5: IAS 1 | H5: Equity | I5: -1
A6: 2024-01-01 | B6: T02 | C6: Legal Fees on Share Issuance | D6: Legal Expense | E6: Dr | F6: 50000 | G6: IAS 1 | H6: Operating | I6: 1
A7: 2024-01-01 | B7: T02 | C7: Legal Fees on Share Issuance | D7: Cash | E7: Cr | F7: 50000 | G7: IAS 1 | H7: Operating | I7: -1
A8: 2024-01-03 | B8: T03 | C8: Machinery Purchase | D8: Machinery | E8: Dr | F8: =Variable_Matrix!C6 | G8: IAS 16 | H8: Investing | I8: 1
A9: 2024-01-03 | B9: T03 | C9: Machinery Purchase | D9: Cash | E9: Cr | F9: =Variable_Matrix!C6 | G9: IAS 16 | H9: Investing | I9: -1
A10: 2024-01-04 | B10: T04 | C10: Land Purchase | D10: Land | E10: Dr | F10: =Variable_Matrix!C15 | G10: IAS 16 | H10: Investing | I10: 1
A11: 2024-01-04 | B11: T04 | C11: Land Purchase | D11: Cash | E11: Cr | F11: =Variable_Matrix!C15 | G11: IAS 16 | H11: Investing | I11: -1
A12: 2024-01-05 | B12: T05 | C12: Land Revaluation — OCI | D12: Land | E12: Dr | F12: =Variable_Matrix!C16 | G12: IAS 16 | H12: OCI | I12: 1
A13: 2024-01-05 | B13: T05 | C13: Land Revaluation — OCI | D13: Revaluation Surplus (OCI) | E13: Cr | F13: =Variable_Matrix!C16 | G13: IAS 16 | H13: OCI | I13: -1
A14: 2024-01-06 | B14: T06 | C14: Inventory Purchase Batch 1 (credit) | D14: Inventory | E14: Dr | F14: 100000 | G14: IAS 2 | H14: Operating | I14: 1
A15: 2024-01-06 | B15: T06 | C15: Inventory Purchase Batch 1 (credit) | D15: Accounts Payable | E15: Cr | F15: 100000 | G15: IAS 2 | H15: Operating | I15: -1
A16: 2024-01-07 | B16: T07 | C16: Sale 1 — on credit | D16: Accounts Receivable | E16: Dr | F16: 93000 | G16: IAS 1 | H16: Operating | I16: 1
A17: 2024-01-07 | B17: T07 | C17: Sale 1 — on credit | D17: Sales Revenue | E17: Cr | F17: 93000 | G17: IAS 1 | H17: Operating | I17: -1
A18: 2024-01-07 | B18: T08 | C18: COGS — Batch 1 (FIFO) | D18: Cost of Sales | E18: Dr | F18: 60000 | G18: IAS 2 | H18: Operating | I18: 1
A19: 2024-01-07 | B19: T08 | C19: COGS — Batch 1 (FIFO) | D19: Inventory | E19: Cr | F19: 60000 | G19: IAS 2 | H19: Operating | I19: -1
A20: 2024-01-08 | B20: T09 | C20: Collection from Customer | D20: Cash | E20: Dr | F20: 74400 | G20: IAS 1 | H20: Operating | I20: 1
A21: 2024-01-08 | B21: T09 | C21: Collection from Customer | D21: Accounts Receivable | E21: Cr | F21: 74400 | G21: IAS 1 | H21: Operating | I21: -1
A22: 2024-01-09 | B22: T10 | C22: Inventory Purchase Batch 2 (cash) | D22: Inventory | E22: Dr | F22: 60000 | G22: IAS 2 | H22: Operating | I22: 1
A23: 2024-01-09 | B23: T10 | C23: Inventory Purchase Batch 2 (cash) | D23: Cash | E23: Cr | F23: 60000 | G23: IAS 2 | H23: Operating | I23: -1
A24: 2024-01-10 | B24: T11 | C24: Sale 2 — cash | D24: Cash | E24: Dr | F24: 74400 | G24: IAS 1 | H24: Operating | I24: 1
A25: 2024-01-10 | B25: T11 | C25: Sale 2 — cash | D25: Sales Revenue | E25: Cr | F25: 74400 | G25: IAS 1 | H25: Operating | I25: -1
... A33: 2024-01-14 | B33: T15 | C33: Bad Debt Expense | D33: Accounts Receivable | E33: Cr | F33: 5000 | G33: IAS 1 | H33: Operating | I33: -1
A34: 2024-01-15 | B34: T16 | C34: Research Expense — expensed (IAS 38) | D34: Research Expense | E34: Dr | F34: =Variable_Matrix!C11 | G34: IAS 38 | H34: Operating | I34: 1
A35: 2024-01-15 | B35: T16 | C35: Research Expense — expensed (IAS 38) | D35: Cash | E35: Cr | F35: =Variable_Matrix!C11 | G35: IAS 38 | H35: Operating | I35: -1
A36: 2024-01-16 | B36: T17 | C36: Development Cost Capitalised (IAS 38) | D36: Intangible Asset — Dev Cost | E36: Dr | F36: =Variable_Matrix!C12 | G36: IAS 38 | H36: Investing | I36: 1
A37: 2024-01-16 | B37: T17 | C37: Development Cost Capitalised (IAS 38) | D37: Cash | E37: Cr | F37: =Variable_Matrix!C12 | G37: IAS 38 | H37: Investing | I37: -1
A38: 2024-01-17 | B38: T18 | C38: IFRS 16 — ROU Asset Recognition | D38: Right-of-Use Asset | E38: Dr | F38: =Variable_Matrix!C17 | G38: IFRS 16 | H38: Financing | I38: 1
A39: 2024-01-17 | B39: T18 | C39: IFRS 16 — Lease Liability Recognition | D39: Lease Liability | E39: Cr | F39: =Variable_Matrix!C17 | G39: IFRS 16 | H39: Financing | I39: -1
A40: 2024-01-17 | B40: T19 | C40: IFRS 16 PV Check: =PV(13%,5,-450000) | D40: [Memo — No JE] | E40: Dr | F40: 0 | G40: IFRS 16 | H40: Memo | I40: 0
A41: 2024-01-31 | B41: T20 | C41: Lease Interest — Year 1 | D41: Interest Expense | E41: Dr | F41: 207619 | G41: IFRS 16 | H41: Operating | I41: 1
A42: 2024-01-31 | B42: T20 | C42: Lease Interest — Year 1 | D42: Lease Liability | E42: Cr | F42: 207619 | G42: IFRS 16 | H42: Operating | I42: -1
A43: 2024-02-01 | B43: T21 | C43: Provision for Legal Claim (IAS 37) | D43: Legal Expense — Provision | E43: Dr | F43: 300000 | G43: IAS 37 | H43: Operating | I43: 1
A44: 2024-02-01 | B44: T21 | C44: Provision for Legal Claim (IAS 37) | D44: Provision Liability | E44: Cr | F44: 300000 | G44: IAS 37 | H44: Operating | I44: -1
A45: 2024-02-01 | B45: T22 | C45: Contingent Liability — Disclosure Only (IAS 37) | D45: [No JE — Disclosure] | E45: Dr | F45: 0 | G45: IAS 37 | H45: Memo | I45: 0
A46: 2024-02-01 | B46: T23 | C46: Impairment Indicator Assessment (IAS 36) — No JE | D46: [Assessment Only] | E46: Dr | F46: 0 | G46: IAS 36 | H46: Memo | I46: 0
A47: 2024-02-01 | B47: T24 | C47: Impairment Loss on Machinery | D47: Impairment Loss | E47: Dr | F47: 2000000 | G47: IAS 36 | H47: Operating | I47: 1
...

Sheet General_Ledger
A1: GENERAL LEDGER — Auto-Posting from Journal via SUMIF
A2: Account | B2: Type | C2: Class | D2: Total Debits | E2: Total Credits | F2: Net Balance | G2: Normal Side
A3: Cash | B3: Asset | C3: Dr-side | D3: =SUMPRODUCT((Journal!D3:D71=A3)*(Journal!I3:I71=1)*Journal!F3:F71) | E3: =SUMPRODUCT((Journal!D3:D71=A3)*(Journal!I3:I71=-1)*Journal!F3:F71) | F3: =D3-E3 | G3: Dr
A4: Accounts Receivable | B4: Asset | C4: Dr-side | D4: =SUMPRODUCT((Journal!D3:D71=A4)*(Journal!I3:I71=1)*Journal!F3:F71) | E4: =SUMPRODUCT((Journal!D3:D71=A4)*(Journal!I3:I71=-1)*Journal!F3:F71) | F4: =D4-E4 | G4: Dr
A5: Inventory | B5: Asset | C5: Dr-side | D5: =SUMPRODUCT((Journal!D3:D71=A5)*(Journal!I3:I71=1)*Journal!F3:F71) | E5: =SUMPRODUCT((Journal!D3:D71=A5)*(Journal!I3:I71=-1)*Journal!F3:F71) | F5: =D5-E5 | G5: Dr
A6: Prepaid Insurance | B6: Asset | C6: Dr-side | D6: =SUMPRODUCT((Journal!D3:D71=A6)*(Journal!I3:I71=1)*Journal!F3:F71) | E6: =SUMPRODUCT((Journal!D3:D71=A6)*(Journal!I3:I71=-1)*Journal!F3:F71) | F6: =D6-E6 | G6: Dr
A7: Machinery | B7: Asset | C7: Dr-side | D7: =SUMPRODUCT((Journal!D3:D71=A7)*(Journal!I3:I71=1)*Journal!F3:F71) | E7: =SUMPRODUCT((Journal!D3:D71=A7)*(Journal!I3:I71=-1)*Journal!F3:F71) | F7: =D7-E7 | G7: Dr
A8: Land | B8: Asset | C8: Dr-side | D8: =SUMPRODUCT((Journal!D3:D71=A8)*(Journal!I3:I71=1)*Journal!F3:F71) | E8: =SUMPRODUCT((Journal!D3:D71=A8)*(Journal!I3:I71=-1)*Journal!F3:F71) | F8: =D8-E8 | G8: Dr
A9: Right-of-Use Asset | B9: Asset | C9: Dr-side | D9: =SUMPRODUCT((Journal!D3:D71=A9)*(Journal!I3:I71=1)*Journal!F3:F71) | E9: =SUMPRODUCT((Journal!D3:D71=A9)*(Journal!I3:I71=-1)*Journal!F3:F71) | F9: =D9-E9 | G9: Dr
A10: Intangible Asset — Dev Cost | B10: Asset | C10: Dr-side | D10: =SUMPRODUCT((Journal!D3:D71=A10)*(Journal!I3:I71=1)*Journal!F3:F71) | E10: =SUMPRODUCT((Journal!D3:D71=A10)*(Journal!I3:I71=-1)*Journal!F3:F71) | F10: =D10-E10 | G10: Dr
A11: Accum. Depreciation — Machinery | B11: Contra | C11: Cr-side | D11: =SUMPRODUCT((Journal!D3:D71=A11)*(Journal!I3:I71=1)*Journal!F3:F71) | E11: =SUMPRODUCT((Journal!D3:D71=A11)*(Journal!I3:I71=-1)*Journal!F3:F71) | F11: =E11-D11 | G11: Cr
A12: Accum. Impairment — Machinery | B12: Contra | C12: Cr-side | D12: =SUMPRODUCT((Journal!D3:D71=A12)*(Journal!I3:I71=1)*Journal!F3:F71) | E12: =SUMPRODUCT((Journal!D3:D71=A12)*(Journal!I3:I71=-1)*Journal!F3:F71) | F12: =E12-D12 | G12: Cr
A13: Accum. Amortisation — Intangible | B13: Contra | C13: Cr-side | D13: =SUMPRODUCT((Journal!D3:D71=A13)*(Journal!I3:I71=1)*Journal!F3:F71) | E13: =SUMPRODUCT((Journal!D3:D71=A13)*(Journal!I3:I71=-1)*Journal!F3:F71) | F13: =E13-D13 | G13: Cr
A14: Accounts Payable | B14: Liability | C14: Cr-side | D14: =SUMPRODUCT((Journal!D3:D71=A14)*(Journal!I3:I71=1)*Journal!F3:F71) | E14: =SUMPRODUCT((Journal!D3:D71=A14)*(Journal!I3:I71=-1)*Journal!F3:F71) | F14: =E14-D14 | G14: Cr
A15: Utilities Payable | B15: Liability | C15: Cr-side | D15: =SUMPRODUCT((Journal!D3:D71=A15)*(Journal!I3:I71=1)*Journal!F3:F71) | E15: =SUMPRODUCT((Journal!D3:D71=A15)*(Journal!I3:I71=-1)*Journal!F3:F71) | F15: =E15-D15 | G15: Cr
A16: Dividend Payable | B16: Liability | C16: Cr-side | D16: =SUMPRODUCT((Journal!D3:D71=A16)*(Journal!I3:I71=1)*Journal!F3:F71) | E16: =SUMPRODUCT((Journal!D3:D71=A16)*(Journal!I3:I71=-1)*Journal!F3:F71) | F16: =E16-D16 | G16: Cr
A17: Lease Liability | B17: Liability | C17: Cr-side | D17: =SUMPRODUCT((Journal!D3:D71=A17)*(Journal!I3:I71=1)*Journal!F3:F71) | E17: =SUMPRODUCT((Journal!D3:D71=A17)*(Journal!I3:I71=-1)*Journal!F3:F71) | F17: =E17-D17 | G17: Cr
A18: Provision Liability | B18: Liability | C18: Cr-side | D18: =SUMPRODUCT((Journal!D3:D71=A18)*(Journal!I3:I71=1)*Journal!F3:F71) | E18: =SUMPRODUCT((Journal!D3:D71=A18)*(Journal!I3:I71=-1)*Journal!F3:F71) | F18: =E18-D18 | G18: Cr
A19: Share Capital | B19: Equity | C19: Cr-side | D19: =SUMPRODUCT((Journal!D3:D71=A19)*(Journal!I3:I71=1)*Journal!F3:F71) | E19: =SUMPRODUCT((Journal!D3:D71=A19)*(Journal!I3:I71=-1)*Journal!F3:F71) | F19: =E19-D19 | G19: Cr
A20: Share Premium | B20: Equity | C20: Cr-side | D20: =SUMPRODUCT((Journal!D3:D71=A20)*(Journal!I3:I71=1)*Journal!F3:F71) | E20: =SUMPRODUCT((Journal!D3:D71=A20)*(Journal!I3:I71=-1)*Journal!F3:F71) | F20: =E20-D20 | G20: Cr
A21: Revaluation Surplus (OCI) | B21: Equity | C21: Cr-side | D21: =SUMPRODUCT((Journal!D3:D71=A21)*(Journal!I3:I71=1)*Journal!F3:F71) | E21: =SUMPRODUCT((Journal!D3:D71=A21)*(Journal!I3:I71=-1)*Journal!F3:F71) | F21: =E21-D21 | G21: Cr
A22: Retained Earnings | B22: Equity | C22: Cr-side | D22: =SUMPRODUCT((Journal!D3:D71=A22)*(Journal!I3:I71=1)*Journal!F3:F71) | E22: =SUMPRODUCT((Journal!D3:D71=A22)*(Journal!I3:I71=-1)*Journal!F3:F71) | F22: =E22-D22 | G22: Cr
A23: Treasury Shares | B23: Contra-Eq | C23: Dr-side | D23: =SUMPRODUCT((Journal!D3:D71=A23)*(Journal!I3:I71=1)*Journal!F3:F71) | E23: =SUMPRODUCT((Journal!D3:D71=A23)*(Journal!I3:I71=-1)*Journal!F3:F71) | F23: =D23-E23 | G23: Dr
A24: Sales Revenue | B24: Revenue | C24: Cr-side | D24: =SUMPRODUCT((Journal!D3:D71=A24)*(Journal!I3:I71=1)*Journal!F3:F71) | E24: =SUMPRODUCT((Journal!D3:D71=A24)*(Journal!I3:I71=-1)*Journal!F3:F71) | F24: =E24-D24 | G24: Cr
A25: Sales Returns & Allowances | B25: Expense | C25: Dr-side | D25: =SUMPRODUCT((Journal!D3:D71=A25)*(Journal!I3:I71=1)*Journal!F3:F71) | E25: =SUMPRODUCT((Journal!D3:D71=A25)*(Journal!I3:I71=-1)*Journal!F3:F71) | F25: =D25-E25 | G25: Dr
A26: Cost of Sales | B26: Expense | C26: Dr-side | D26: =SUMPRODUCT((Journal!D3:D71=A26)*(Journal!I3:I71=1)*Journal!F3:F71) | E26: =SUMPRODUCT((Journal!D3:D71=A26)*(Journal!I3:I71=-1)*Journal!F3:F71) | F26: =D26-E26 | G26: Dr
A27: Inventory Write-Down Loss | B27: Expense | C27: Dr-side | D27: =SUMPRODUCT((Journal!D3:D71=A27)*(Journal!I3:I71=1)*Journal!F3:F71) | E27: =SUMPRODUCT((Journal!D3:D71=A27)*(Journal!I3:I71=-1)*Journal!F3:F71) | F27: =D27-E27 | G27: Dr
A28: Legal Expense | B28: Expense | C28: Dr-side | D28: =SUMPRODUCT((Journal!D3:D71=A28)*(Journal!I3:I71=1)*Journal!F3:F71) | E28: =SUMPRODUCT((Journal!D3:D71=A28)*(Journal!I3:I71=-1)*Journal!F3:F71) | F28: =D28-E28 | G28: Dr
A29: Legal Expense — Provision | B29: Expense | C29: Dr-side | D29: =SUMPRODUCT((Journal!D3:D71=A29)*(Journal!I3:I71=1)*Journal!F3:F71) | E29: =SUMPRODUCT((Journal!D3:D71=A29)*(Journal!I3:I71=-1)*Journal!F3:F71) | F29: =D29-E29 | G29: Dr
A30: Bad Debt Expense | B30: Expense | C30: Dr-side | D30: =SUMPRODUCT((Journal!D3:D71=A30)*(Journal!I3:I71=1)*Journal!F3:F71) | E30: =SUMPRODUCT((Journal!D3:D71=A30)*(Journal!I3:I71=-1)*Journal!F3:F71) | F30: =D30-E30 | G30: Dr
A31: Research Expense | B31: Expense | C31: Dr-side | D31: =SUMPRODUCT((Journal!D3:D71=A31)*(Journal!I3:I71=1)*Journal!F3:F71) | E31: =SUMPRODUCT((Journal!D3:D71=A31)*(Journal!I3:I71=-1)*Journal!F3:F71) | F31: =D31-E31 | G31: Dr
A32: Depreciation Expense | B32: Expense | C32: Dr-side | D32: =SUMPRODUCT((Journal!D3:D71=A32)*(Journal!I3:I71=1)*Journal!F3:F71) | E32: =SUMPRODUCT((Journal!D3:D71=A32)*(Journal!I3:I71=-1)*Journal!F3:F71) | F32: =D32-E32 | G32: Dr
A33: Amortisation Expense | B33: Expense | C33: Dr-side | D33: =SUMPRODUCT((Journal!D3:D71=A33)*(Journal!I3:I71=1)*Journal!F3:F71) | E33: =SUMPRODUCT((Journal!D3:D71=A33)*(Journal!I3:I71=-1)*Journal!F3:F71) | F33: =D33-E33 | G33: Dr
A34: Impairment Loss | B34: Expense | C34: Dr-side | D34: =SUMPRODUCT((Journal!D3:D71=A34)*(Journal!I3:I71=1)*Journal!F3:F71) | E34: =SUMPRODUCT((Journal!D3:D71=A34)*(Journal!I3:I71=-1)*Journal!F3:F71) | F34: =D34-E34 | G34: Dr
A35: Interest Expense | B35: Expense | C35: Dr-side | D35: =SUMPRODUCT((Journal!D3:D71=A35)*(Journal!I3:I71=1)*Journal!F3:F71) | E35: =SUMPRODUCT((Journal!D3:D71=A35)*(Journal!I3:I71=-1)*Journal!F3:F71) | F35: =D35-E35 | G35: Dr
A36: Insurance Expense | B36: Expense | C36: Dr-side | D36: =SUMPRODUCT((Journal!D3:D71=A36)*(Journal!I3:I71=1)*Journal!F3:F71) | E36: =SUMPRODUCT((Journal!D3:D71=A36)*(Journal!I3:I71=-1)*Journal!F3:F71) | F36: =D36-E36 | G36: Dr
A37: Utilities Expense | B37: Expense | C37: Dr-side | D37: =SUMPRODUCT((Journal!D3:D71=A37)*(Journal!I3:I71=1)*Journal!F3:F71) | E37: =SUMPRODUCT((Journal!D3:D71=A37)*(Journal!I3:I71=-1)*Journal!F3:F71) | F37: =D37-E37 | G37: Dr
A38: Salaries Expense | B38: Expense | C38: Dr-side | D38: =SUMPRODUCT((Journal!D3:D71=A38)*(Journal!I3:I71=1)*Journal!F3:F71) | E38: =SUMPRODUCT((Journal!D3:D71=A38)*(Journal!I3:I71=-1)*Journal!F3:F71) | F38: =D38-E38 | G38: Dr

Sheet Trial_Balance
A1: TRIAL BALANCE — As at 31 December 2024
A2: Account Name | B2: Type | C2: Debit (PKR) | D2: Credit (PKR) | E2: Source
A3: Cash | B3: Asset | C3: =IF(General_Ledger!F3>0,General_Ledger!F3,0) | E3: Cash
A4: Accounts Receivable | B4: Asset | C4: =IF(General_Ledger!F4>0,General_Ledger!F4,0) | E4: Accounts Receivable
A5: Inventory | B5: Asset | C5: =IF(General_Ledger!F5>0,General_Ledger!F5,0) | E5: Inventory
A6: Prepaid Insurance | B6: Asset | C6: =IF(General_Ledger!F6>0,General_Ledger!F6,0) | E6: Prepaid Insurance
A7: Machinery | B7: Asset | C7: =IF(General_Ledger!F7>0,General_Ledger!F7,0) | E7: Machinery
A8: Land | B8: Asset | C8: =IF(General_Ledger!F8>0,General_Ledger!F8,0) | E8: Land
A9: Right-of-Use Asset | B9: Asset | C9: =IF(General_Ledger!F9>0,General_Ledger!F9,0) | E9: Right-of-Use Asset
A10: Intangible Asset — Dev Cost | B10: Asset | C10: =IF(General_Ledger!F10>0,General_Ledger!F10,0) | E10: Intangible Asset — Dev Cost
A11: Accum. Depreciation — Machinery | B11: Contra | D11: =IF(General_Ledger!F11>0,General_Ledger!F11,0) | E11: Accum. Depreciation — Machinery
A12: Accum. Impairment — Machinery | B12: Contra | D12: =IF(General_Ledger!F12>0,General_Ledger!F12,0) | E12: Accum. Impairment — Machinery
A13: Accum. Amortisation — Intangible | B13: Contra | D13: =IF(General_Ledger!F13>0,General_Ledger!F13,0) | E13: Accum. Amortisation — Intangible
A14: Accounts Payable | B14: Liability | D14: =IF(General_Ledger!F14>0,General_Ledger!F14,0) | E14: Accounts Payable
A15: Utilities Payable | B15: Liability | D15: =IF(General_Ledger!F15>0,General_Ledger!F15,0) | E15: Utilities Payable
A16: Dividend Payable | B16: Liability | D16: =IF(General_Ledger!F16>0,General_Ledger!F16,0) | E16: Dividend Payable
A17: Lease Liability | B17: Liability | D17: =IF(General_Ledger!F17>0,General_Ledger!F17,0) | E17: Lease Liability
A18: Provision Liability | B18: Liability | D18: =IF(General_Ledger!F18>0,General_Ledger!F18,0) | E18: Provision Liability
A19: Share Capital | B19: Equity | D19: =IF(General_Ledger!F19>0,General_Ledger!F19,0) | E19: Share Capital
A20: Share Premium | B20: Equity | D20: =IF(General_Ledger!F20>0,General_Ledger!F20,0) | E20: Share Premium
A21: Revaluation Surplus (OCI) | B21: Equity | D21: =IF(General_Ledger!F21>0,General_Ledger!F21,0) | E21: Revaluation Surplus (OCI)
A22: Retained Earnings | B22: Equity | D22: =IF(General_Ledger!F22>0,General_Ledger!F22,0) | E22: Retained Earnings
A23: Treasury Shares | B23: Contra-Eq | C23: =IF(General_Ledger!F23>0,General_Ledger!F23,0) | E23: Treasury Shares
A24: Sales Revenue | B24: Revenue | D24: =IF(General_Ledger!F24>0,General_Ledger!F24,0) | E24: Sales Revenue
A25: Sales Returns & Allowances | B25: Expense | C25: =IF(General_Ledger!F25>0,General_Ledger!F25,0) | E25: Sales Returns & Allowances
A26: Cost of Sales | B26: Expense | C26: =IF(General_Ledger!F26>0,General_Ledger!F26,0) | E26: Cost of Sales
A27: Inventory Write-Down Loss | B27: Expense | C27: =IF(General_Ledger!F27>0,General_Ledger!F27,0) | E27: Inventory Write-Down Loss
A28: Legal Expense | B28: Expense | C28: =IF(General_Ledger!F28>0,General_Ledger!F28,0) | E28: Legal Expense
A29: Legal Expense — Provision | B29: Expense | C29: =IF(General_Ledger!F29>0,General_Ledger!F29,0) | E29: Legal Expense — Provision
A30: Bad Debt Expense | B30: Expense | C30: =IF(General_Ledger!F30>0,General_Ledger!F30,0) | E30: Bad Debt Expense
A31: Research Expense | B31: Expense | C31: =IF(General_Ledger!F31>0,General_Ledger!F31,0) | E31: Research Expense
A32: Depreciation Expense | B32: Expense | C32: =IF(General_Ledger!F32>0,General_Ledger!F32,0) | E32: Depreciation Expense
A33: Amortisation Expense | B33: Expense | C33: =IF(General_Ledger!F33>0,General_Ledger!F33,0) | E33: Amortisation Expense
A34: Impairment Loss | B34: Expense | C34: =IF(General_Ledger!F34>0,General_Ledger!F34,0) | E34: Impairment Loss
A35: Interest Expense | B35: Expense | C35: =IF(General_Ledger!F35>0,General_Ledger!F35,0) | E35: Interest Expense
A36: Insurance Expense | B36: Expense | C36: =IF(General_Ledger!F36>0,General_Ledger!F36,0) | E36: Insurance Expense
... A38: Salaries Expense | B38: Expense | C38: =IF(General_Ledger!F38>0,General_Ledger!F38,0) | E38: Salaries Expense
A39: TOTALS | C39: =SUM(C3:C38) | D39: =SUM(D3:D38)
A41: Balance Check: | C41: =IF(ABS(C39-D39)<1,"✔ BALANCED","✘ ERROR")

Sheet Inventory_Module
A1: INVENTORY MODULE — IAS 2 | FIFO Costing & NRV Test
A2: Batch | B2: Date | C2: Units In | D2: Cost/Unit (PKR) | E2: Total Cost | F2: Units Sold | G2: COGS | H2: Closing Units
A3: B1 | B3: 2024-01-06 | C3: 100 | D3: 1000 | E3: =C3*D3 | F3: 60 | G3: =F3*D3 | H3: =C3-F3
A4: B2 | B4: 2024-01-09 | C4: 60 | D4: 1000 | E4: =C4*D4 | F4: 40 | G4: =F4*D4 | H4: =C4-F4
A7: NRV ANALYSIS — IAS 2.9
A8: Closing Inventory — Cost: | C8: =H3*D3+H4*D4
A9: Net Realisable Value (NRV): | C9: 99000 | D9: IAS 2 estimate
A10: Write-Down Required: | C10: =MAX(0,C8-C9) | D10: =MAX(0, Cost - NRV)
A13: SUMMARY
A14: Total COGS: | C14: =G3+G4
A15: Closing Inventory (after write-down): | C15: =C8-C10

Sheet PPE_Module
A1: PPE MODULE — IAS 16 | IAS 36 Impairment
A2: Asset | B2: Cost | C2: Accum. Depr. | D2: Impairment | E2: Carrying Amt | F2: Recoverable | G2: Imp. Loss
A3: Machinery | B3: =Variable_Matrix!C6 | C3: =Variable_Matrix!C6/Variable_Matrix!C14 | D3: 2000000 | E3: =B3-C3-D3 | F3: =Variable_Matrix!C13 | G3: =MAX(0,B3-D3-F3)
A4: Land | B4: =Variable_Matrix!C15+Variable_Matrix!C16 | C4: 0 | D4: 0 | E4: =B4 | F4: N/A | G4: 0
A6: Revaluation Surplus (Land): | C6: =Variable_Matrix!C16
A8: STRAIGHT-LINE DEPRECIATION SCHEDULE — Machinery
A9: Year | B9: Opening CA | C9: Annual Depr. | D9: Impairment | E9: Closing CA | F9: Accum Depr | G9: Accum Imp
A10: 1 | B10: =Variable_Matrix!C6 | C10: =Variable_Matrix!C6/Variable_Matrix!C14 | D10: 2000000 | E10: =B10-C10-D10 | F10: =SUM(C$10:C10) | G10: =SUM(D$10:D10)
A11: 2 | B11: =E10 | C11: =Variable_Matrix!C6/Variable_Matrix!C14 | D11: 0 | E11: =B11-C11-D11 | F11: =SUM(C$10:C11) | G11: =SUM(D$10:D11)
A12: 3 | B12: =E11 | C12: =Variable_Matrix!C6/Variable_Matrix!C14 | D12: 0 | E12: =B12-C12-D12 | F12: =SUM(C$10:C12) | G12: =SUM(D$10:D12)

Sheet Lease_Module
A1: LEASE MODULE — IFRS 16 | Amortisation Schedule
A2: Annual Lease Payment (PKR): | C2: =Variable_Matrix!C8
A3: Discount Rate: | C3: =Variable_Matrix!C9
A4: Lease Term (Years): | C4: =Variable_Matrix!C10
A5: PV of Lease Liability (ROU): | C5: =PV(C3,C4,-C2) | D5: ← IFRS 16 initial measurement basis
A7: Year | B7: Opening Liability | C7: Interest (13%) | D7: Lease Payment | E7: Principal | F7: Closing Liability | G7: ROU Depr
A8: 1 | B8: =C5 | C8: =B8*C$3 | D8: =C$2 | E8: =D8-C8 | F8: =B8-E8 | G8: =C$5/C$4
A9: 2 | B9: =F8 | C9: =B9*C$3 | D9: =C$2 | E9: =D9-C9 | F9: =B9-E9 | G9: =C$5/C$4
A10: 3 | B10: =F9 | C10: =B10*C$3 | D10: =C$2 | E10: =D10-C10 | F10: =B10-E10 | G10: =C$5/C$4
A11: 4 | B11: =F10 | C11: =B11*C$3 | D11: =C$2 | E11: =D11-C11 | F11: =B11-E11 | G11: =C$5/C$4
A12: 5 | B12: =F11 | C12: =B12*C$3 | D12: =C$2 | E12: =D12-C12 | F12: =B12-E12 | G12: =C$5/C$4
A13: Totals | C13: =SUM(C8:C12) | D13: =SUM(D8:D12) | E13: =SUM(E8:E12) | G13: =SUM(G8:G12)

Sheet Equity_Module
A1: STATEMENT OF CHANGES IN EQUITY — Year Ended 31 December 2024
A2: Item | B2: Share Capital | C2: Share Premium | D2: Ret. Earnings | E2: Reval. Surplus | F2: Treasury Shares | G2: Total Equity
A3: Opening Balance (1 Jan 2024) | B3: 0 | C3: 0 | D3: 0 | E3: 0 | F3: 0 | G3: =SUM(B3:F3)
A4: T01 — Share Issuance | B4: =General_Ledger!E19-General_Ledger!D19 | C4: =General_Ledger!E20-General_Ledger!D20 | D4: 0 | E4: 0 | F4: 0 | G4: =SUM(B4:F4)
A5: T05 — Revaluation Surplus | B5: 0 | C5: 0 | D5: 0 | E5: =Variable_Matrix!C16 | F5: 0 | G5: =SUM(B5:F5)
A6: T27/T28 — Dividends | B6: 0 | C6: 0 | D6: -810000 | E6: 0 | F6: 0 | G6: =SUM(B6:F6)
A7: T29 — Bonus Issue | B7: 275000 | C7: 0 | D7: -275000 | E7: 0 | F7: 0 | G7: =SUM(B7:F7)
A8: T30 — Private Placement | B8: 500000 | C8: 1150000 | D8: 0 | E8: 0 | F8: 0 | G8: =SUM(B8:F8)
A9: T26 — Treasury Shares | B9: 0 | C9: 0 | D9: 0 | E9: 0 | F9: -300000 | G9: =SUM(B9:F9)
A10: Net Profit for Year | B10: 0 | C10: 0 | D10: =Profit_Loss!C37 | E10: 0 | F10: 0 | G10: =SUM(B10:F10)
A11: Closing Balance (31 Dec 2024) | B11: =General_Ledger!F19 | C11: =General_Ledger!F20 | D11: =General_Ledger!F22 | E11: =General_Ledger!F21 | F11: =-General_Ledger!F23 | G11: =SUM(B11:F11)

Sheet Profit_Loss
A1: STATEMENT OF PROFIT OR LOSS — Year Ended 31 December 2024
A2: Prepared in Accordance with IAS 1 (Revised)
A3: Description | B3: IFRS Ref | C3: Amount (PKR) | D3: Notes
A4: REVENUE
A5: Sales Revenue | B5: IAS 1 | C5: =General_Ledger!F24 | D5: T07+T11
A6: Less: Sales Returns | B6: IAS 1 | C6: =-General_Ledger!F25 | D6: T12
A7: Net Revenue | C7: =C5+C6
A9: COST OF SALES
A10: Cost of Goods Sold | B10: IAS 2 | C10: =-General_Ledger!F26 | D10: T08
A11: Inventory Write-Down | B11: IAS 2 | C11: =-General_Ledger!F27 | D11: T13
A12: Total Cost of Sales | C12: =-(C9+C10)
A14: GROSS PROFIT | C14: =C7+C11
A16: OPERATING EXPENSES
A17: Depreciation — Machinery | B17: IAS 16 | C17: =-General_Ledger!F32 | D17: T31
A18: Amortisation — Dev Cost | B18: IAS 38 | C18: =-General_Ledger!F33 | D18: T25
A19: Impairment Loss | B19: IAS 36 | C19: =-General_Ledger!F34 | D19: T24
A20: Research Expense | B20: IAS 38 | C20: =-General_Ledger!F31 | D20: T16
A21: Legal Expense | B21: IAS 37 | C21: =-(General_Ledger!F28+General_Ledger!F29) | D21: T02+T21
A22: Bad Debt Expense | B22: IAS 1 | C22: =-General_Ledger!F30 | D22: T15
A23: Insurance Expense | B23: IAS 1 | C23: =-General_Ledger!F36 | D23: T33
A24: Utilities Expense | B24: IAS 1 | C24: =-General_Ledger!F37 | D24: T34
A25: Salaries Expense | B25: IAS 1 | C25: =-General_Ledger!F38 | D25: T35
A26: Total Operating Expenses | C26: =SUM(C15:C25)
A28: OPERATING PROFIT (EBIT) | C28: =C12+C26
A30: FINANCE COSTS
A31: Interest Expense — Lease | B31: IFRS 16 | C31: =-General_Ledger!F35 | D31: T20
A33: PROFIT BEFORE TAX | C33: =C28+C31
A34: Income Tax Expense | B34: IAS 12 | C34: =0
A35: NET PROFIT FOR THE YEAR | C35: =C32+C33
A37: OTHER COMPREHENSIVE INCOME
A38: Revaluation Surplus — Land | B38: IAS 16 | C38: =General_Ledger!F21 | D38: T05
A39: TOTAL COMPREHENSIVE INCOME | C39: =C34+C38

Sheet SOFP
A1: STATEMENT OF FINANCIAL POSITION — As at 31 December 2024
A2: Prepared in Accordance with IAS 1
A3: Description | B3: Note | C3: Amount (PKR) | D3: IFRS Ref
A4: NON-CURRENT ASSETS
A5: Machinery — Cost | C5: =General_Ledger!F7 | D5: IAS 16
A6: Less: Accum. Depreciation | C6: =-General_Ledger!F11 | D6: IAS 16
A7: Less: Accum. Impairment | C7: =-General_Ledger!F12 | D7: IAS 36
A8: Machinery — Net Carrying Amount | C8: =C5+C6+C7
A9: Land (incl. Revaluation) | C9: =General_Ledger!F8 | D9: IAS 16
A10: Right-of-Use Asset — Cost | C10: =General_Ledger!F9 | D10: IFRS 16
A11: Less: ROU Accumulated Depr. | C11: =-Lease_Module!G8 | D11: IFRS 16
A12: ROU Asset — Net | C12: =C10+C11
A13: Intangible Asset — Dev Cost | C13: =General_Ledger!F10 | D13: IAS 38
A14: Less: Accum. Amortisation | C14: =-General_Ledger!F13 | D14: IAS 38
A15: Intangible — Net | C15: =C14+C15
A16: TOTAL NON-CURRENT ASSETS | C16: =C8+C9+C12+C16
A18: CURRENT ASSETS
A19: Inventories | C19: =General_Ledger!F5 | D19: IAS 2
A20: Accounts Receivable (net) | C20: =General_Ledger!F4 | D20: IAS 1
A21: Prepaid Insurance | C21: =General_Ledger!F6 | D21: IAS 1
A22: Cash and Cash Equivalents | C22: =General_Ledger!F3 | D22: IAS 7
A23: TOTAL CURRENT ASSETS | C23: =SUM(C20:C23)
A25: TOTAL ASSETS | C25: =C17+C24
A27: EQUITY
A28: Share Capital | C28: =General_Ledger!F19 | D28: IAS 1
A29: Share Premium | C29: =General_Ledger!F20 | D29: IAS 1
A30: Retained Earnings | C30: =General_Ledger!F22 | D30: IAS 1
A31: Revaluation Surplus (OCI) | C31: =General_Ledger!F21 | D31: IAS 16
A32: Less: Treasury Shares | C32: =-General_Ledger!F23 | D32: IAS 32
A33: TOTAL EQUITY | C33: =SUM(C28:C32)
A35: NON-CURRENT LIABILITIES
A36: Lease Liability (non-current) | C36: =General_Ledger!F17 | D36: IFRS 16
A37: Provision Liability | C37: =General_Ledger!F18 | D37: IAS 37
A38: TOTAL NON-CURRENT LIABILITIES | C38: =C37+C38
A40: CURRENT LIABILITIES
A41: Accounts Payable | C41: =General_Ledger!F14 | D41: IAS 1
A42: Utilities Payable | C42: =General_Ledger!F15 | D42: IAS 1
A43: Dividend Payable | C43: =General_Ledger!F16 | D43: IAS 1
A44: TOTAL CURRENT LIABILITIES | C44: =SUM(C43:C45)
A46: TOTAL LIABILITIES | C46: =C39+C46
...

Sheet Cash_Flow
A1: STATEMENT OF CASH FLOWS — Year Ended 31 December 2024
A2: Indirect Method — IAS 7
A3: Description | B3: Ref | C3: Amount (PKR) | D3: IAS 7 Note
A4: OPERATING ACTIVITIES
A5: Net Profit for the Year | B5: PL | C5: =Profit_Loss!C35 | D5: Start: Net Profit
A6: Add: Depreciation (non-cash) | B6: T31 | C6: =ABS(General_Ledger!F32) | D6: Non-cash add-back
A7: Add: Amortisation (non-cash) | B7: T25 | C7: =ABS(General_Ledger!F33) | D7: Non-cash add-back
A8: Add: Impairment (non-cash) | B8: T24 | C8: =ABS(General_Ledger!F34) | D8: Non-cash add-back
A9: Add: Bad Debt (non-cash) | B9: T15 | C9: =ABS(General_Ledger!F30) | D9: Non-cash add-back
A10: Working Capital Changes:
A11: (Inc)/Dec in Receivables | C11: =-General_Ledger!F4 | D11: Current asset Δ
A12: (Inc)/Dec in Inventories | C12: =-General_Ledger!F5 | D12: Current asset Δ
A13: (Inc)/Dec in Prepayments | C13: =-General_Ledger!F6 | D13: Current asset Δ
A14: Inc/(Dec) in Payables | C14: =General_Ledger!F14 | D14: Current liability Δ
A15: Inc/(Dec) in Utilities Payable | C15: =General_Ledger!F15 | D15: Current liability Δ
A16: NET CASH FROM OPERATING ACTIVITIES | C16: =SUM(C5:C16)
A18: INVESTING ACTIVITIES
A19: Purchase of Machinery | B19: T03 | C19: =-Variable_Matrix!C6 | D19: IAS 7
A20: Purchase of Land | B20: T04 | C20: =-Variable_Matrix!C15 | D20: IAS 7
A21: Development Costs Capitalised | B21: T17 | C21: =-Variable_Matrix!C12 | D21: IAS 38
A22: NET CASH USED IN INVESTING | C22: =SUM(C20:C22)
A24: FINANCING ACTIVITIES
A25: Proceeds — Share Issuance | B25: T01 | C25: =Variable_Matrix!C3*Variable_Matrix!C4 | D25: IAS 7
A26: Proceeds — Private Placement | B26: T30 | C26: =1650000 | D26: IAS 7
A27: Treasury Share Buyback | B27: T26 | C27: =-300000 | D27: IAS 7
A28: Dividends Paid | B28: T28 | C28: =-810000 | D28: IAS 7
A29: Lease Payment — Principal | B29: T18 | C29: =-Lease_Module!E8 | D29: IFRS 16
A30: NET CASH FROM FINANCING | C30: =SUM(C25:C29)
A32: NET INC/(DEC) IN CASH | C32: =C17+C23+C30
A33: Opening Cash Balance | C33: =0
A34: CLOSING CASH BALANCE | C34: =C32+C33
A35: GL Cash Verification | C35: =IF(ABS(C34-General_Ledger!F3)<1,"✔ MATCHES GL","✘ DISCREPANCY")

Sheet Notes_Disclosures
A1: NOTES TO THE FINANCIAL STATEMENTS — Group 8 | FY 2024
A2: NOTE 1 — BASIS OF PREPARATION (IAS 1)
A3: These financial statements have been prepared in accordance with International Financial Reporting Standards (IFRS) as issued by the IASB. Standards applied include IAS 1 (Revised), IAS 2 (Inventories), IAS 7 (Cash Flows), IAS 16 (PPE), IAS 36 (Impairment), IAS 37 (Provisions), IAS 38 (Intangibles), IAS 32 (Financial Instruments — Equity), and IFRS 16 (Leases). Amounts are stated in Pakistani Rupees (PKR).
A5: NOTE 2 — CONTINGENT LIABILITY (IAS 37 / T22)
A6: A third-party legal claim exists for which the company cannot make a reliable estimate of the outflow. No provision has been recognised. In accordance with IAS 37.86, this is disclosed as a contingent liability. The claim is assessed as possible but not probable. Legal counsel is reviewing the matter.
A8: NOTE 3 — IMPAIRMENT OF MACHINERY (IAS 36 / T23–T24)
A9: An impairment indicator (technological obsolescence) was identified. An impairment test compared the Carrying Amount of PKR 19,666,667 (Cost PKR 20,000,000 less Depreciation PKR 333,333) against Recoverable Amount PKR 18,000,000 (higher of Fair Value Less Costs of Disposal and Value in Use). Impairment loss of PKR 2,000,000 was recognised in profit or loss.
A11: NOTE 4 — LEASE (IFRS 16 / T18–T20)
A12: The company entered a 5-year lease with annual payments of PKR 450,000. Under IFRS 16, a right-of-use asset and lease liability were recognised at PV = PKR 1,597,065, calculated as =PV(13%,5,-450,000). Interest at 13% is accreted annually. Year 1 interest = PKR 207,619. Principal repayment = PKR 242,381.
A14: NOTE 5 — INTANGIBLE ASSETS (IAS 38 / T16–T17 / T25)
A15: Research expenditure of PKR 75,000 was expensed as incurred (IAS 38.54 — does not qualify for capitalisation). Development costs of PKR 220,000 met all six IAS 38.57 criteria and were capitalised as an intangible asset. Amortisation is over 10 years on a straight-line basis (annual PKR 22,000; monthly PKR 1,833).
A17: NOTE 6 — EQUITY TRANSACTIONS (IAS 1 / IAS 32)
... A24: A provision of PKR 300,000 was recognised for a probable legal obligation arising from a third-party claim where a reliable estimate was available. The provision represents management's best estimate of the expenditure required to settle the present obligation at the reporting date.

Sheet AI_Log
A1: AI PROMPT LOG — IFRS Accounting Engine Build Record
A2: Step | B2: Prompt Summary | C2: AI Output Summary | D2: Standards Used
A3: 1 | B3: Build 35-transaction IFRS journal with Group 8 variables (expanded Dr/Cr rows) | C3: Generated expanded debit/credit entries T01-T35 with D/C flag column for SUMPRODUCT | D3: Multiple
A4: 2 | B4: Create FIFO inventory engine under IAS 2 | C4: Batch costing engine, NRV write-down test, COGS and closing inventory formulas | D4: IAS 2
A5: 3 | B5: Build IFRS 16 lease amortisation table | C5: PV =PV(13%,5,-450000), 5-year interest/principal split schedule | D5: IFRS 16
A6: 4 | B6: IAS 16 depreciation and IAS 36 impairment module | C6: SL depreciation 60yr; impairment test: CA vs Recoverable Amount → PKR 2M loss | D6: IAS 16/36
A7: 5 | B7: IAS 38 research vs development split | C7: Research PKR 75k expensed; Dev PKR 220k capitalised, amortised 10yr SL | D7: IAS 38
A8: 6 | B8: General Ledger via SUMPRODUCT from Journal | C8: Used SUMPRODUCT with D/C flag to auto-post debits and credits to ledger | D8: All
A9: 7 | B9: Link GL to Trial Balance and all Financial Statements | C9: Cross-sheet formulas: GL→TB→P&L→SOFP→SCE→CF all auto-update | D9: IAS 1
A10: 8 | B10: Dashboard KPI cards and financial summaries | C10: Live KPIs: Cash, Net Profit, Total Assets, Equity, Current Ratio, Debt Ratio | D10: IAS 1
A11: 9 | B11: Cash Flow — Indirect Method | C11: Net profit → non-cash add-backs → WC changes → investing → financing | D11: IAS 7
A12: 10 | B12: Accounting equation validation and balance checks | C12: =IF(ABS(Assets-(E+L))<1,'BALANCED','ERROR') on Dashboard and SOFP | D12: IAS 1

Sheet Input_Form
A1: TRANSACTION INPUT FORM — Add New Entries
A2: Instructions: Fill in the yellow cells below. Then copy the row and paste into the Journal sheet (row after last transaction). The ledger, TB, and all statements update automatically via SUMPRODUCT formulas.
A4: Date (YYYY-MM-DD): | B4: 2024-01-01 | C4: Format: 2024-MM-DD
A5: Transaction ID: | B5: T36 | C5: Unique ID e.g. T36, T37
A6: Description: | B6: Enter here | C6: Brief description of transaction
A7: Account: | B7: Cash | C7: Debit or Credit account name — must match GL
A8: Dr / Cr: | B8: Dr | C8: Type 'Dr' for debit or 'Cr' for credit
A9: Amount (PKR): | B9: 0 | C9: Positive number only
A10: IFRS Reference: | B10: IAS 1 | C10: e.g. IAS 1, IAS 2, IFRS 16
A11: Category: | B11: Operating | C11: Operating / Investing / Financing / Equity / OCI
A12: D/C Flag (1=Dr, -1=Cr, 0=Memo): | B12: 1 | C12: 1 for Dr, -1 for Cr, 0 for memo entries
